Workbook

Sheet 00_Dashboard & Tổng Quan
B2: 4TMUSIC — DASHBOARD & TỔNG QUAN DỰ ÁN
B3: ="Tự động cập nhật từ sheet 01 & 03 & 04 • Hôm nay: "&TEXT(TODAY(),"dd/mm/yyyy")&" • Tuần hiện tại: "&CFG_CurWeek&" / "&CFG_Weeks -> Tự động cập nhật từ sheet 01 & 03 & 04 • Hôm nay: 12/10/2026 • Tuần hiện tại: 1 / 34
B5: THÔNG TIN DỰ ÁN
B6: Tên dự án | C6: 4TMusic — Nền tảng nghe nhạc trực tuyến, nghe offline
B7: Loại hình | C7: Nền tảng âm nhạc · Web App (React/Vite + Node/Express + MySQL) · PWA nghe offline · Mobile App Flutter (sau Release)
B8: Quy mô nhân sự | C8: 1 người: Nhật đảm nhận FE, BE, Database, UI/UX, QA, DevOps. Có sẵn 3 vị trí UI/UX, QA, Mobile/DevOps trong sheet 05 nếu mở rộng nhóm.
B9: Thời gian phát triển | C9: =CFG_Weeks&" tuần (≈ 8 tháng, 2–3 giờ/ngày): Tuần 1 = "&TEXT(CFG_Start,"dd/mm/yyyy")&" → kết thúc "&TEXT(CFG_Start+CFG_Weeks*7-1,"dd/mm/yyyy")&" • 10 giai đoạn GĐ0–GĐ9" -> 34 tuần (≈ 8 tháng, 2–3 giờ/ngày): Tuần 1 = 12/10/2026 → kết thúc 06/06/2027 • 10 giai đoạn GĐ0–GĐ9
B10: Milestone | C10: =INDEX(MS_Names,1)&": tuần "&INDEX(MS_Weeks,1)&" • "&INDEX(MS_Names,2)&": tuần "&INDEX(MS_Weeks,2)&" • "&INDEX(MS_Names,3)&": tuần "&INDEX(MS_Weeks,3) -> Release Alpha: tuần 21 • Release Beta: tuần 27 • Release Production: tuần 34
B11: Nguồn nhạc | C11: Nhạc Creative Commons (Jamendo API, Free Music Archive) + nghệ sĩ tự upload có cam kết bản quyền; chỉ cho tải offline bài có license cho phép
B12: Công nghệ | C12: React, Tailwind, Zustand, TanStack Query · Node.js/Express, Prisma, MySQL, Redis · Cloudflare R2, FFmpeg · PWA (Workbox) · Docker, Vercel/Render, GitHub Actions
B14: CHỈ SỐ CHÍNH (KPI)
B15: TIẾN ĐỘ TASK | C15: % TIẾN ĐỘ TỔNG | D15: TỔNG TASK | E15: HOÀN THÀNH | F15: ĐANG LÀM | G15: TRỄ HẠN | H15: BLOCKED | I15: CÒN LẠI
C16: =IFERROR(SUM(W_DoneDays)/SUM(W_Days),0) -> 0.0029411765 | D16: =COUNTIF(W_Task,"?*") -> 76 | E16: =COUNTIF(W_Status,"Done") -> 0 | F16: =COUNTIF(W_Status,"In Progress") -> 1 | G16: =COUNTIF(W_Alert,"⚠ Trễ hạn") -> 0 | H16: =COUNTIF(W_Status,"Blocked") -> 0 | I16: =COUNTIF(W_Status,"To Do") -> 75
C17: theo ngày công | D17: trong WBS | E17: Done | F17: In Progress | G17: quá Tuần KT | H17: đang bị chặn | I17: To Do
B19: API · UX · THỜI GIAN | C19: API DEV XONG | D19: % API XONG | E19: API TEST PASS | F19: API TEST FAIL | G19: UX ĐÃ XỬ LÝ | H19: TUẦN HIỆN TẠI | I19: ĐẾN PRODUCTION
C20: =COUNTIF(A_Dev,"Done")&" / "&COUNTIF(A_Endpoint,"?*") -> 0 / 83 | D20: =IFERROR(COUNTIF(A_Dev,"Done")/COUNTIF(A_Endpoint,"?*"),0) -> 0 | E20: =COUNTIF(A_Test,"Pass") -> 0 | F20: =COUNTIF(A_Test,"Fail") -> 0 | G20: =COUNTIF(U_Done,TRUE())&" / "&COUNTIF(U_Item,"?*") -> 0 / 22 | H20: =CFG_CurWeek&" / "&CFG_Weeks -> 1 / 34 | I20: =MAX(0,CFG_Start+INDEX(MS_Weeks,3)*7-1-TODAY()) -> 237
C21: endpoint | D21: Dev Done | E21: đã kiểm thử đạt | F21: cần sửa | G21: backlog sheet 04 | H21: của dự án | I21: ngày còn lại
B23: TIẾN ĐỘ THEO GIAI ĐOẠN (PHASE)
B24: Giai đoạn | C24: Tuần | D24: Số task | E24: Done | F24: In Progress | G24: Trễ hạn | H24: % hoàn thành | I24: Milestone
B25: ='05_Settings & Reference'!D11 -> GĐ0: Khởi động & nền tảng | C25: ='05_Settings & Reference'!E11&"–"&'05_Settings & Reference'!F11 -> 1–2 | D25: =COUNTIF(W_Phase,$B25) -> 6 | E25: =COUNTIFS(W_Phase,$B25,W_Status,"Done") -> 0 | F25: =COUNTIFS(W_Phase,$B25,W_Status,"In Progress") -> 1 | G25: =COUNTIFS(W_Phase,$B25,W_Alert,"⚠ Trễ hạn") -> 0 | H25: =IFERROR(SUMIFS(W_DoneDays,W_Phase,$B25)/SUMIFS(W_Days,W_Phase,$B25),0) -> 0.042857143 | I25: =IFERROR(INDEX(MS_Names,MATCH('05_Settings & Reference'!F11,MS_Weeks,0)),"")
B26: ='05_Settings & Reference'!D12 -> GĐ1: Giao diện tĩnh (HTML/CSS) | C26: ='05_Settings & Reference'!E12&"–"&'05_Settings & Reference'!F12 -> 3–5 | D26: =COUNTIF(W_Phase,$B26) -> 7 | E26: =COUNTIFS(W_Phase,$B26,W_Status,"Done") -> 0 | F26: =COUNTIFS(W_Phase,$B26,W_Status,"In Progress") -> 0 | G26: =COUNTIFS(W_Phase,$B26,W_Alert,"⚠ Trễ hạn") -> 0 | H26: =IFERROR(SUMIFS(W_DoneDays,W_Phase,$B26)/SUMIFS(W_Days,W_Phase,$B26),0) -> 0 | I26: =IFERROR(INDEX(MS_Names,MATCH('05_Settings & Reference'!F12,MS_Weeks,0)),"")
B27: ='05_Settings & Reference'!D13 -> GĐ2: Trình phát nhạc (JavaScript) | C27: ='05_Settings & Reference'!E13&"–"&'05_Settings & Reference'!F13 -> 6–9 | D27: =COUNTIF(W_Phase,$B27) -> 7 | E27: =COUNTIFS(W_Phase,$B27,W_Status,"Done") -> 0 | F27: =COUNTIFS(W_Phase,$B27,W_Status,"In Progress") -> 0 | G27: =COUNTIFS(W_Phase,$B27,W_Alert,"⚠ Trễ hạn") -> 0 | H27: =IFERROR(SUMIFS(W_DoneDays,W_Phase,$B27)/SUMIFS(W_Days,W_Phase,$B27),0) -> 0 | I27: =IFERROR(INDEX(MS_Names,MATCH('05_Settings & Reference'!F13,MS_Weeks,0)),"")
B28: ='05_Settings & Reference'!D14 -> GĐ3: Frontend React | C28: ='05_Settings & Reference'!E14&"–"&'05_Settings & Reference'!F14 -> 10–13 | D28: =COUNTIF(W_Phase,$B28) -> 7 | E28: =COUNTIFS(W_Phase,$B28,W_Status,"Done") -> 0 | F28: =COUNTIFS(W_Phase,$B28,W_Status,"In Progress") -> 0 | G28: =COUNTIFS(W_Phase,$B28,W_Alert,"⚠ Trễ hạn") -> 0 | H28: =IFERROR(SUMIFS(W_DoneDays,W_Phase,$B28)/SUMIFS(W_Days,W_Phase,$B28),0) -> 0 | I28: =IFERROR(INDEX(MS_Names,MATCH('05_Settings & Reference'!F14,MS_Weeks,0)),"")
B29: ='05_Settings & Reference'!D15 -> GĐ4: Backend & Streaming API | C29: ='05_Settings & Reference'!E15&"–"&'05_Settings & Reference'!F15 -> 14–17 | D29: =COUNTIF(W_Phase,$B29) -> 7 | E29: =COUNTIFS(W_Phase,$B29,W_Status,"Done") -> 0 | F29: =COUNTIFS(W_Phase,$B29,W_Status,"In Progress") -> 0 | G29: =COUNTIFS(W_Phase,$B29,W_Alert,"⚠ Trễ hạn") -> 0 | H29: =IFERROR(SUMIFS(W_DoneDays,W_Phase,$B29)/SUMIFS(W_Days,W_Phase,$B29),0) -> 0 | I29: =IFERROR(INDEX(MS_Names,MATCH('05_Settings & Reference'!F15,MS_Weeks,0)),"")
B30: ='05_Settings & Reference'!D16 -> GĐ5: Database & dữ liệu nhạc | C30: ='05_Settings & Reference'!E16&"–"&'05_Settings & Reference'!F16 -> 18–21 | D30: =COUNTIF(W_Phase,$B30) -> 8 | E30: =COUNTIFS(W_Phase,$B30,W_Status,"Done") -> 0 | F30: =COUNTIFS(W_Phase,$B30,W_Status,"In Progress") -> 0 | G30: =COUNTIFS(W_Phase,$B30,W_Alert,"⚠ Trễ hạn") -> 0 | H30: =IFERROR(SUMIFS(W_DoneDays,W_Phase,$B30)/SUMIFS(W_Days,W_Phase,$B30),0) -> 0 | I30: =IFERROR(INDEX(MS_Names,MATCH('05_Settings & Reference'!F16,MS_Weeks,0)),"") -> Release Alpha
B31: ='05_Settings & Reference'!D17 -> GĐ6: Tài khoản & thư viện cá nhân | C31: ='05_Settings & Reference'!E17&"–"&'05_Settings & Reference'!F17 -> 22–24 | D31: =COUNTIF(W_Phase,$B31) -> 9 | E31: =COUNTIFS(W_Phase,$B31,W_Status,"Done") -> 0 | F31: =COUNTIFS(W_Phase,$B31,W_Status,"In Progress") -> 0 | G31: =COUNTIFS(W_Phase,$B31,W_Alert,"⚠ Trễ hạn") -> 0 | H31: =IFERROR(SUMIFS(W_DoneDays,W_Phase,$B31)/SUMIFS(W_Days,W_Phase,$B31),0) -> 0 | I31: =IFERROR(INDEX(MS_Names,MATCH('05_Settings & Reference'!F17,MS_Weeks,0)),"")
B32: ='05_Settings & Reference'!D18 -> GĐ7: Cloud, Admin & Artist Panel | C32: ='05_Settings & Reference'!E18&"–"&'05_Settings & Reference'!F18 -> 25–27 | D32: =COUNTIF(W_Phase,$B32) -> 7 | E32: =COUNTIFS(W_Phase,$B32,W_Status,"Done") -> 0 | F32: =COUNTIFS(W_Phase,$B32,W_Status,"In Progress") -> 0 | G32: =COUNTIFS(W_Phase,$B32,W_Alert,"⚠ Trễ hạn") -> 0 | H32: =IFERROR(SUMIFS(W_DoneDays,W_Phase,$B32)/SUMIFS(W_Days,W_Phase,$B32),0) -> 0 | I32: =IFERROR(INDEX(MS_Names,MATCH('05_Settings & Reference'!F18,MS_Weeks,0)),"") -> Release Beta
B33: ='05_Settings & Reference'!D19 -> GĐ8: Offline PWA & lời bài hát | C33: ='05_Settings & Reference'!E19&"–"&'05_Settings & Reference'!F19 -> 28–30 | D33: =COUNTIF(W_Phase,$B33) -> 8 | E33: =COUNTIFS(W_Phase,$B33,W_Status,"Done") -> 0 | F33: =COUNTIFS(W_Phase,$B33,W_Status,"In Progress") -> 0 | G33: =COUNTIFS(W_Phase,$B33,W_Alert,"⚠ Trễ hạn") -> 0 | H33: =IFERROR(SUMIFS(W_DoneDays,W_Phase,$B33)/SUMIFS(W_Days,W_Phase,$B33),0) -> 0 | I33: =IFERROR(INDEX(MS_Names,MATCH('05_Settings & Reference'!F19,MS_Weeks,0)),"")
B34: ='05_Settings & Reference'!D20 -> GĐ9: Bảo mật, triển khai & Release | C34: ='05_Settings & Reference'!E20&"–"&'05_Settings & Reference'!F20 -> 31–34 | D34: =COUNTIF(W_Phase,$B34) -> 10 | E34: =COUNTIFS(W_Phase,$B34,W_Status,"Done") -> 0 | F34: =COUNTIFS(W_Phase,$B34,W_Status,"In Progress") -> 0 | G34: =COUNTIFS(W_Phase,$B34,W_Alert,"⚠ Trễ hạn") -> 0 | H34: =IFERROR(SUMIFS(W_DoneDays,W_Phase,$B34)/SUMIFS(W_Days,W_Phase,$B34),0) -> 0 | I34: =IFERROR(INDEX(MS_Names,MATCH('05_Settings & Reference'!F20,MS_Weeks,0)),"") -> Release Production
B35: TỔNG | D35: =SUM(D25:D34) -> 76 | E35: =SUM(E25:E34) -> 0 | F35: =SUM(F25:F34) -> 1 | G35: =SUM(G25:G34) -> 0 | H35: =IFERROR(SUM(W_DoneDays)/SUM(W_Days),0) -> 0.0029411765
B37: TIẾN ĐỘ THEO MODULE (EPIC)
B38: Module | C38: Số task | D38: Done | E38: In Progress | F38: To Do | G38: Blocked | H38: Trễ hạn | I38: % hoàn thành
B39: ='05_Settings & Reference'!I11 -> Nền tảng & Hạ tầng | C39: =COUNTIF(W_Module,$B39) -> 12 | D39: =COUNTIFS(W_Module,$B39,W_Status,"Done") -> 0 | E39: =COUNTIFS(W_Module,$B39,W_Status,"In Progress") -> 1 | F39: =COUNTIFS(W_Module,$B39,W_Status,"To Do") -> 11 | G39: =COUNTIFS(W_Module,$B39,W_Status,"Blocked") -> 0 | H39: =COUNTIFS(W_Module,$B39,W_Alert,"⚠ Trễ hạn") -> 0 | I39: =IFERROR(SUMIFS(W_DoneDays,W_Module,$B39)/SUMIFS(W_Days,W_Module,$B39),0) -> 0.01875
B40: ='05_Settings & Reference'!I12 -> Giao diện chung (Layout/Theme) | C40: =COUNTIF(W_Module,$B40) -> 9 | D40: =COUNTIFS(W_Module,$B40,W_Status,"Done") -> 0 | E40: =COUNTIFS(W_Module,$B40,W_Status,"In Progress") -> 0 | F40: =COUNTIFS(W_Module,$B40,W_Status,"To Do") -> 9 | G40: =COUNTIFS(W_Module,$B40,W_Status,"Blocked") -> 0 | H40: =COUNTIFS(W_Module,$B40,W_Alert,"⚠ Trễ hạn") -> 0 | I40: =IFERROR(SUMIFS(W_DoneDays,W_Module,$B40)/SUMIFS(W_Days,W_Module,$B40),0) -> 0
B41: ='05_Settings & Reference'!I13 -> Phát nhạc & Player | C41: =COUNTIF(W_Module,$B41) -> 11 | D41: =COUNTIFS(W_Module,$B41,W_Status,"Done") -> 0 | E41: =COUNTIFS(W_Module,$B41,W_Status,"In Progress") -> 0 | F41: =COUNTIFS(W_Module,$B41,W_Status,"To Do") -> 11 | G41: =COUNTIFS(W_Module,$B41,W_Status,"Blocked") -> 0 | H41: =COUNTIFS(W_Module,$B41,W_Alert,"⚠ Trễ hạn") -> 0 | I41: =IFERROR(SUMIFS(W_DoneDays,W_Module,$B41)/SUMIFS(W_Days,W_Module,$B41),0) -> 0
B42: ='05_Settings & Reference'!I14 -> Tìm kiếm & Khám phá | C42: =COUNTIF(W_Module,$B42) -> 7 | D42: =COUNTIFS(W_Module,$B42,W_Status,"Done") -> 0 | E42: =COUNTIFS(W_Module,$B42,W_Status,"In Progress") -> 0 | F42: =COUNTIFS(W_Module,$B42,W_Status,"To Do") -> 7 | G42: =COUNTIFS(W_Module,$B42,W_Status,"Blocked") -> 0 | H42: =COUNTIFS(W_Module,$B42,W_Alert,"⚠ Trễ hạn") -> 0 | I42: =IFERROR(SUMIFS(W_DoneDays,W_Module,$B42)/SUMIFS(W_Days,W_Module,$B42),0) -> 0
B43: ='05_Settings & Reference'!I15 -> Streaming & Lưu trữ | C43: =COUNTIF(W_Module,$B43) -> 7 | D43: =COUNTIFS(W_Module,$B43,W_Status,"Done") -> 0 | E43: =COUNTIFS(W_Module,$B43,W_Status,"In Progress") -> 0 | F43: =COUNTIFS(W_Module,$B43,W_Status,"To Do") -> 7 | G43: =COUNTIFS(W_Module,$B43,W_Status,"Blocked") -> 0 | H43: =COUNTIFS(W_Module,$B43,W_Alert,"⚠ Trễ hạn") -> 0 | I43: =IFERROR(SUMIFS(W_DoneDays,W_Module,$B43)/SUMIFS(W_Days,W_Module,$B43),0) -> 0
B44: ='05_Settings & Reference'!I16 -> Xác thực & Người dùng | C44: =COUNTIF(W_Module,$B44) -> 5 | D44: =COUNTIFS(W_Module,$B44,W_Status,"Done") -> 0 | E44: =COUNTIFS(W_Module,$B44,W_Status,"In Progress") -> 0 | F44: =COUNTIFS(W_Module,$B44,W_Status,"To Do") -> 5 | G44: =COUNTIFS(W_Module,$B44,W_Status,"Blocked") -> 0 | H44: =COUNTIFS(W_Module,$B44,W_Alert,"⚠ Trễ hạn") -> 0 | I44: =IFERROR(SUMIFS(W_DoneDays,W_Module,$B44)/SUMIFS(W_Days,W_Module,$B44),0) -> 0
B45: ='05_Settings & Reference'!I17 -> Playlist | C45: =COUNTIF(W_Module,$B45) -> 2 | D45: =COUNTIFS(W_Module,$B45,W_Status,"Done") -> 0 | E45: =COUNTIFS(W_Module,$B45,W_Status,"In Progress") -> 0 | F45: =COUNTIFS(W_Module,$B45,W_Status,"To Do") -> 2 | G45: =COUNTIFS(W_Module,$B45,W_Status,"Blocked") -> 0 | H45: =COUNTIFS(W_Module,$B45,W_Alert,"⚠ Trễ hạn") -> 0 | I45: =IFERROR(SUMIFS(W_DoneDays,W_Module,$B45)/SUMIFS(W_Days,W_Module,$B45),0) -> 0
B46: ='05_Settings & Reference'!I18 -> Thư viện cá nhân | C46: =COUNTIF(W_Module,$B46) -> 2 | D46: =COUNTIFS(W_Module,$B46,W_Status,"Done") -> 0 | E46: =COUNTIFS(W_Module,$B46,W_Status,"In Progress") -> 0 | F46: =COUNTIFS(W_Module,$B46,W_Status,"To Do") -> 2 | G46: =COUNTIFS(W_Module,$B46,W_Status,"Blocked") -> 0 | H46: =COUNTIFS(W_Module,$B46,W_Alert,"⚠ Trễ hạn") -> 0 | I46: =IFERROR(SUMIFS(W_DoneDays,W_Module,$B46)/SUMIFS(W_Days,W_Module,$B46),0) -> 0
...

Sheet 01_WBS & Master Plan
A1: 01 — WBS & MASTER PLAN · 4TMUSIC
A2: Ô nền trắng: nhập liệu (dùng dropdown). Cột xám J, O–R: công thức tự động — không sửa. Số ngày = số tuần × 5 ngày làm việc. Trạng thái Done được tính 100% dù cột % chưa nhập.
A4: Mã WBS | B4: Giai đoạn (Phase) | C4: Module (Epic) | D4: Công việc chi tiết (Task) | E4: Người phụ trách | F4: Loại công việc | G4: Ưu tiên | H4: Tuần BĐ | I4: Tuần KT | J4: Số ngày dự kiến | K4: Trạng thái | L4: % Hoàn thành | M4: Kết quả bàn giao (Deliverable) | N4: Ghi chú | O4: Ngày BĐ | P4: Ngày KT | Q4: Cảnh báo | R4: Ngày công đã xong
A5: 0.1 | B5: GĐ0: Khởi động & nền tảng | C5: Nền tảng & Hạ tầng | D5: Học: web hoạt động thế nào — client/server, DNS, HTTP request/response, status code | E5: Nhật | F5: Học tập | G5: High | H5: 1 | I5: 1 | J5: =IF(OR(H5="",I5=""),"",(I5-H5+1)*5) -> 5 | K5: In Progress | L5: 0.3 | M5: Ghi chú kiến thức (Notion/Markdown) | N5: MDN "How the web works"; roadmap.sh | O5: =IF(H5="","",CFG_Start+(H5-1)*7) -> 46307 | P5: =IF(I5="","",CFG_Start+I5*7-1) -> 46313 | Q5: =IF(D5="","",IF(K5="Done","✔ Xong",IF(K5="Blocked","⛔ Blocked",IF(P5<TODAY(),"⚠ Trễ hạn",IF(O5<=TODAY(),"▶ Trong kỳ","Chưa tới"))))) -> ▶ Trong kỳ | R5: =IF(J5="",0,J5*IF(K5="Done",1,IF(L5="",0,L5))) -> 1.5
A6: 0.2 | B6: GĐ0: Khởi động & nền tảng | C6: Nền tảng & Hạ tầng | D6: Cài môi trường: VS Code (Prettier, ESLint), Node.js LTS, Git, Postman, Chrome DevTools | E6: Nhật | F6: DevOps | G6: High | H6: 1 | I6: 1 | J6: =IF(OR(H6="",I6=""),"",(I6-H6+1)*5) -> 5 | K6: To Do | L6: 0 | M6: Môi trường dev chạy được | O6: =IF(H6="","",CFG_Start+(H6-1)*7) -> 46307 | P6: =IF(I6="","",CFG_Start+I6*7-1) -> 46313 | Q6: =IF(D6="","",IF(K6="Done","✔ Xong",IF(K6="Blocked","⛔ Blocked",IF(P6<TODAY(),"⚠ Trễ hạn",IF(O6<=TODAY(),"▶ Trong kỳ","Chưa tới"))))) -> ▶ Trong kỳ | R6: =IF(J6="",0,J6*IF(K6="Done",1,IF(L6="",0,L6))) -> 0
A7: 0.3 | B7: GĐ0: Khởi động & nền tảng | C7: Nền tảng & Hạ tầng | D7: Học Git cơ bản; tạo repo GitHub 4TMusic (client/ + server/), README, .gitignore | E7: Nhật | F7: DevOps | G7: High | H7: 1 | I7: 2 | J7: =IF(OR(H7="",I7=""),"",(I7-H7+1)*5) -> 10 | K7: To Do | L7: 0 | M7: Repo + commit đầu tiên | N7: Commit mỗi ngày | O7: =IF(H7="","",CFG_Start+(H7-1)*7) -> 46307 | P7: =IF(I7="","",CFG_Start+I7*7-1) -> 46320 | Q7: =IF(D7="","",IF(K7="Done","✔ Xong",IF(K7="Blocked","⛔ Blocked",IF(P7<TODAY(),"⚠ Trễ hạn",IF(O7<=TODAY(),"▶ Trong kỳ","Chưa tới"))))) -> ▶ Trong kỳ | R7: =IF(J7="",0,J7*IF(K7="Done",1,IF(L7="",0,L7))) -> 0
A8: 0.4 | B8: GĐ0: Khởi động & nền tảng | C8: Nền tảng & Hạ tầng | D8: Viết tài liệu yêu cầu rút gọn: tính năng, vai trò (Khách, User, Artist, Admin), phạm vi P1/P2 | E8: Nhật | F8: Docs | G8: High | H8: 2 | I8: 2 | J8: =IF(OR(H8="",I8=""),"",(I8-H8+1)*5) -> 5 | K8: To Do | L8: 0 | M8: SRS rút gọn v0.1 | O8: =IF(H8="","",CFG_Start+(H8-1)*7) -> 46314 | P8: =IF(I8="","",CFG_Start+I8*7-1) -> 46320 | Q8: =IF(D8="","",IF(K8="Done","✔ Xong",IF(K8="Blocked","⛔ Blocked",IF(P8<TODAY(),"⚠ Trễ hạn",IF(O8<=TODAY(),"▶ Trong kỳ","Chưa tới"))))) -> Chưa tới | R8: =IF(J8="",0,J8*IF(K8="Done",1,IF(L8="",0,L8))) -> 0
A9: 0.5 | B9: GĐ0: Khởi động & nền tảng | C9: Giao diện chung (Layout/Theme) | D9: Phác wireframe: Trang chủ, Tìm kiếm, Album, Nghệ sĩ, Playlist, Thư viện, Player bar, Now Playing | E9: Nhật | F9: UI | G9: Medium | H9: 2 | I9: 2 | J9: =IF(OR(H9="",I9=""),"",(I9-H9+1)*5) -> 5 | K9: To Do | L9: 0 | M9: Wireframe Figma | N9: Tham khảo bố cục app nghe nhạc phổ biến | O9: =IF(H9="","",CFG_Start+(H9-1)*7) -> 46314 | P9: =IF(I9="","",CFG_Start+I9*7-1) -> 46320 | Q9: =IF(D9="","",IF(K9="Done","✔ Xong",IF(K9="Blocked","⛔ Blocked",IF(P9<TODAY(),"⚠ Trễ hạn",IF(O9<=TODAY(),"▶ Trong kỳ","Chưa tới"))))) -> Chưa tới | R9: =IF(J9="",0,J9*IF(K9="Done",1,IF(L9="",0,L9))) -> 0
A10: 0.6 | B10: GĐ0: Khởi động & nền tảng | C10: Streaming & Lưu trữ | D10: Chốt nguồn nhạc hợp pháp: đăng ký Jamendo API, tải 20–30 bài Creative Commons, lập bảng giấy phép | E10: Nhật | F10: Docs | G10: High | H10: 2 | I10: 2 | J10: =IF(OR(H10="",I10=""),"",(I10-H10+1)*5) -> 5 | K10: To Do | L10: 0 | M10: Bộ nhạc mẫu + bảng license | N10: Chỉ cho tải offline bài có license cho phép | O10: =IF(H10="","",CFG_Start+(H10-1)*7) -> 46314 | P10: =IF(I10="","",CFG_Start+I10*7-1) -> 46320 | Q10: =IF(D10="","",IF(K10="Done","✔ Xong",IF(K10="Blocked","⛔ Blocked",IF(P10<TODAY(),"⚠ Trễ hạn",IF(O10<=TODAY(),"▶ Trong kỳ","Chưa tới"))))) -> Chưa tới | R10: =IF(J10="",0,J10*IF(K10="Done",1,IF(L10="",0,L10))) -> 0
A11: 1.1 | B11: GĐ1: Giao diện tĩnh (HTML/CSS) | C11: Giao diện chung (Layout/Theme) | D11: Học HTML ngữ nghĩa & CSS cơ bản (selector, box model, đơn vị) | E11: Nhật | F11: Học tập | G11: High | H11: 3 | I11: 3 | J11: =IF(OR(H11="",I11=""),"",(I11-H11+1)*5) -> 5 | K11: To Do | L11: 0 | M11: Bài tập nhỏ | N11: MDN Learn HTML/CSS | O11: =IF(H11="","",CFG_Start+(H11-1)*7) -> 46321 | P11: =IF(I11="","",CFG_Start+I11*7-1) -> 46327 | Q11: =IF(D11="","",IF(K11="Done","✔ Xong",IF(K11="Blocked","⛔ Blocked",IF(P11<TODAY(),"⚠ Trễ hạn",IF(O11<=TODAY(),"▶ Trong kỳ","Chưa tới"))))) -> Chưa tới | R11: =IF(J11="",0,J11*IF(K11="Done",1,IF(L11="",0,L11))) -> 0
A12: 1.2 | B12: GĐ1: Giao diện tĩnh (HTML/CSS) | C12: Giao diện chung (Layout/Theme) | D12: Học Flexbox, Grid, responsive (media query, mobile-first) | E12: Nhật | F12: Học tập | G12: High | H12: 3 | I12: 4 | J12: =IF(OR(H12="",I12=""),"",(I12-H12+1)*5) -> 10 | K12: To Do | L12: 0 | M12: Bài tập Flexbox Froggy/Grid Garden | O12: =IF(H12="","",CFG_Start+(H12-1)*7) -> 46321 | P12: =IF(I12="","",CFG_Start+I12*7-1) -> 46334 | Q12: =IF(D12="","",IF(K12="Done","✔ Xong",IF(K12="Blocked","⛔ Blocked",IF(P12<TODAY(),"⚠ Trễ hạn",IF(O12<=TODAY(),"▶ Trong kỳ","Chưa tới"))))) -> Chưa tới | R12: =IF(J12="",0,J12*IF(K12="Done",1,IF(L12="",0,L12))) -> 0
A13: 1.3 | B13: GĐ1: Giao diện tĩnh (HTML/CSS) | C13: Giao diện chung (Layout/Theme) | D13: Dựng layout tĩnh: sidebar menu, header + ô tìm kiếm, vùng nội dung | E13: Nhật | F13: UI | G13: High | H13: 4 | I13: 4 | J13: =IF(OR(H13="",I13=""),"",(I13-H13+1)*5) -> 5 | K13: To Do | L13: 0 | M13: index.html + style.css | O13: =IF(H13="","",CFG_Start+(H13-1)*7) -> 46328 | P13: =IF(I13="","",CFG_Start+I13*7-1) -> 46334 | Q13: =IF(D13="","",IF(K13="Done","✔ Xong",IF(K13="Blocked","⛔ Blocked",IF(P13<TODAY(),"⚠ Trễ hạn",IF(O13<=TODAY(),"▶ Trong kỳ","Chưa tới"))))) -> Chưa tới | R13: =IF(J13="",0,J13*IF(K13="Done",1,IF(L13="",0,L13))) -> 0
A14: 1.4 | B14: GĐ1: Giao diện tĩnh (HTML/CSS) | C14: Tìm kiếm & Khám phá | D14: Dựng trang chủ tĩnh: lưới album, danh sách bài nổi bật, thể loại | E14: Nhật | F14: UI | G14: Medium | H14: 4 | I14: 5 | J14: =IF(OR(H14="",I14=""),"",(I14-H14+1)*5) -> 10 | K14: To Do | L14: 0 | M14: Trang chủ tĩnh | O14: =IF(H14="","",CFG_Start+(H14-1)*7) -> 46328 | P14: =IF(I14="","",CFG_Start+I14*7-1) -> 46341 | Q14: =IF(D14="","",IF(K14="Done","✔ Xong",IF(K14="Blocked","⛔ Blocked",IF(P14<TODAY(),"⚠ Trễ hạn",IF(O14<=TODAY(),"▶ Trong kỳ","Chưa tới"))))) -> Chưa tới | R14: =IF(J14="",0,J14*IF(K14="Done",1,IF(L14="",0,L14))) -> 0
A15: 1.5 | B15: GĐ1: Giao diện tĩnh (HTML/CSS) | C15: Phát nhạc & Player | D15: Dựng thanh Player cố định dưới màn hình (ảnh bìa, tên bài, nút, thanh tiến trình) | E15: Nhật | F15: UI | G15: High | H15: 5 | I15: 5 | J15: =IF(OR(H15="",I15=""),"",(I15-H15+1)*5) -> 5 | K15: To Do | L15: 0 | M15: Player bar tĩnh | N15: Thử <audio controls> phát 1 bài CC | O15: =IF(H15="","",CFG_Start+(H15-1)*7) -> 46335 | P15: =IF(I15="","",CFG_Start+I15*7-1) -> 46341 | Q15: =IF(D15="","",IF(K15="Done","✔ Xong",IF(K15="Blocked","⛔ Blocked",IF(P15<TODAY(),"⚠ Trễ hạn",IF(O15<=TODAY(),"▶ Trong kỳ","Chưa tới"))))) -> Chưa tới | R15: =IF(J15="",0,J15*IF(K15="Done",1,IF(L15="",0,L15))) -> 0
A16: 1.6 | B16: GĐ1: Giao diện tĩnh (HTML/CSS) | C16: Giao diện chung (Layout/Theme) | D16: Giao diện Sáng/Tối bằng CSS variables | E16: Nhật | F16: UI | G16: Low | H16: 5 | I16: 5 | J16: =IF(OR(H16="",I16=""),"",(I16-H16+1)*5) -> 5 | K16: To Do | L16: 0 | M16: Theme toggle | O16: =IF(H16="","",CFG_Start+(H16-1)*7) -> 46335 | P16: =IF(I16="","",CFG_Start+I16*7-1) -> 46341 | Q16: =IF(D16="","",IF(K16="Done","✔ Xong",IF(K16="Blocked","⛔ Blocked",IF(P16<TODAY(),"⚠ Trễ hạn",IF(O16<=TODAY(),"▶ Trong kỳ","Chưa tới"))))) -> Chưa tới | R16: =IF(J16="",0,J16*IF(K16="Done",1,IF(L16="",0,L16))) -> 0
A17: 1.7 | B17: GĐ1: Giao diện tĩnh (HTML/CSS) | C17: Giao diện chung (Layout/Theme) | D17: Kiểm tra responsive ở 3 kích thước (mobile/tablet/laptop) | E17: Nhật | F17: Testing | G17: Medium | H17: 5 | I17: 5 | J17: =IF(OR(H17="",I17=""),"",(I17-H17+1)*5) -> 5 | K17: To Do | L17: 0 | M17: Checklist responsive | O17: =IF(H17="","",CFG_Start+(H17-1)*7) -> 46335 | P17: =IF(I17="","",CFG_Start+I17*7-1) -> 46341 | Q17: =IF(D17="","",IF(K17="Done","✔ Xong",IF(K17="Blocked","⛔ Blocked",IF(P17<TODAY(),"⚠ Trễ hạn",IF(O17<=TODAY(),"▶ Trong kỳ","Chưa tới"))))) -> Chưa tới | R17: =IF(J17="",0,J17*IF(K17="Done",1,IF(L17="",0,L17))) -> 0
A18: 2.1 | B18: GĐ2: Trình phát nhạc (JavaScript) | C18: Phát nhạc & Player | D18: Học JavaScript cơ bản: biến, hàm, mảng, object, map/filter | E18: Nhật | F18: Học tập | G18: High | H18: 6 | I18: 7 | J18: =IF(OR(H18="",I18=""),"",(I18-H18+1)*5) -> 10 | K18: To Do | L18: 0 | M18: Bài tập javascript.info | O18: =IF(H18="","",CFG_Start+(H18-1)*7) -> 46342 | P18: =IF(I18="","",CFG_Start+I18*7-1) -> 46355 | Q18: =IF(D18="","",IF(K18="Done","✔ Xong",IF(K18="Blocked","⛔ Blocked",IF(P18<TODAY(),"⚠ Trễ hạn",IF(O18<=TODAY(),"▶ Trong kỳ","Chưa tới"))))) -> Chưa tới | R18: =IF(J18="",0,J18*IF(K18="Done",1,IF(L18="",0,L18))) -> 0
A19: 2.2 | B19: GĐ2: Trình phát nhạc (JavaScript) | C19: Phát nhạc & Player | D19: Học DOM, sự kiện, fetch, Promise, async/await | E19: Nhật | F19: Học tập | G19: High | H19: 7 | I19: 8 | J19: =IF(OR(H19="",I19=""),"",(I19-H19+1)*5) -> 10 | K19: To Do | L19: 0 | M19: Bài tập DOM | O19: =IF(H19="","",CFG_Start+(H19-1)*7) -> 46349 | P19: =IF(I19="","",CFG_Start+I19*7-1) -> 46362 | Q19: =IF(D19="","",IF(K19="Done","✔ Xong",IF(K19="Blocked","⛔ Blocked",IF(P19<TODAY(),"⚠ Trễ hạn",IF(O19<=TODAY(),"▶ Trong kỳ","Chưa tới"))))) -> Chưa tới | R19: =IF(J19="",0,J19*IF(K19="Done",1,IF(L19="",0,L19))) -> 0
A20: 2.3 | B20: GĐ2: Trình phát nhạc (JavaScript) | C20: Phát nhạc & Player | D20: Player JS thuần: play/pause, thanh tua, thời gian, âm lượng (HTMLAudioElement) | E20: Nhật | F20: FE | G20: High | H20: 8 | I20: 8 | J20: =IF(OR(H20="",I20=""),"",(I20-H20+1)*5) -> 5 | K20: To Do | L20: 0 | M20: player.js | N20: Sự kiện timeupdate, ended | O20: =IF(H20="","",CFG_Start+(H20-1)*7) -> 46356 | P20: =IF(I20="","",CFG_Start+I20*7-1) -> 46362 | Q20: =IF(D20="","",IF(K20="Done","✔ Xong",IF(K20="Blocked","⛔ Blocked",IF(P20<TODAY(),"⚠ Trễ hạn",IF(O20<=TODAY(),"▶ Trong kỳ","Chưa tới"))))) -> Chưa tới | R20: =IF(J20="",0,J20*IF(K20="Done",1,IF(L20="",0,L20))) -> 0
A21: 2.4 | B21: GĐ2: Trình phát nhạc (JavaScript) | C21: Phát nhạc & Player | D21: Danh sách bài lấy từ songs.json (fetch), bấm bài để phát | E21: Nhật | F21: FE | G21: High | H21: 8 | I21: 9 | J21: =IF(OR(H21="",I21=""),"",(I21-H21+1)*5) -> 10 | K21: To Do | L21: 0 | M21: Song list động | O21: =IF(H21="","",CFG_Start+(H21-1)*7) -> 46356 | P21: =IF(I21="","",CFG_Start+I21*7-1) -> 46369 | Q21: =IF(D21="","",IF(K21="Done","✔ Xong",IF(K21="Blocked","⛔ Blocked",IF(P21<TODAY(),"⚠ Trễ hạn",IF(O21<=TODAY(),"▶ Trong kỳ","Chưa tới"))))) -> Chưa tới | R21: =IF(J21="",0,J21*IF(K21="Done",1,IF(L21="",0,L21))) -> 0
A22: 2.5 | B22: GĐ2: Trình phát nhạc (JavaScript) | C22: Phát nhạc & Player | D22: Next/Prev, Shuffle, Repeat (one/all), tự chuyển bài khi hết | E22: Nhật | F22: FE | G22: High | H22: 9 | I22: 9 | J22: =IF(OR(H22="",I22=""),"",(I22-H22+1)*5) -> 5 | K22: To Do | L22: 0 | M22: Điều khiển phát đầy đủ | O22: =IF(H22="","",CFG_Start+(H22-1)*7) -> 46363 | P22: =IF(I22="","",CFG_Start+I22*7-1) -> 46369 | Q22: =IF(D22="","",IF(K22="Done","✔ Xong",IF(K22="Blocked","⛔ Blocked",IF(P22<TODAY(),"⚠ Trễ hạn",IF(O22<=TODAY(),"▶ Trong kỳ","Chưa tới"))))) -> Chưa tới | R22: =IF(J22="",0,J22*IF(K22="Done",1,IF(L22="",0,L22))) -> 0
A23: 2.6 | B23: GĐ2: Trình phát nhạc (JavaScript) | C23: Phát nhạc & Player | D23: Hàng đợi phát (queue): thêm, xóa, phát tiếp theo | E23: Nhật | F23: FE | G23: Medium | H23: 9 | I23: 9 | J23: =IF(OR(H23="",I23=""),"",(I23-H23+1)*5) -> 5 | K23: To Do | L23: 0 | M23: Queue panel | O23: =IF(H23="","",CFG_Start+(H23-1)*7) -> 46363 | P23: =IF(I23="","",CFG_Start+I23*7-1) -> 46369 | Q23: =IF(D23="","",IF(K23="Done","✔ Xong",IF(K23="Blocked","⛔ Blocked",IF(P23<TODAY(),"⚠ Trễ hạn",IF(O23<=TODAY(),"▶ Trong kỳ","Chưa tới"))))) -> Chưa tới | R23: =IF(J23="",0,J23*IF(K23="Done",1,IF(L23="",0,L23))) -> 0
A24: 2.7 | B24: GĐ2: Trình phát nhạc (JavaScript) | C24: Phát nhạc & Player | D24: Kiểm thử player trên Chrome, Firefox, điện thoại | E24: Nhật | F24: Testing | G24: Medium | H24: 9 | I24: 9 | J24: =IF(OR(H24="",I24=""),"",(I24-H24+1)*5) -> 5 | K24: To Do | L24: 0 | M24: Bug list | O24: =IF(H24="","",CFG_Start+(H24-1)*7) -> 46363 | P24: =IF(I24="","",CFG_Start+I24*7-1) -> 46369 | Q24: =IF(D24="","",IF(K24="Done","✔ Xong",IF(K24="Blocked","⛔ Blocked",IF(P24<TODAY(),"⚠ Trễ hạn",IF(O24<=TODAY(),"▶ Trong kỳ","Chưa tới"))))) -> Chưa tới | R24: =IF(J24="",0,J24*IF(K24="Done",1,IF(L24="",0,L24))) -> 0
A25: 3.1 | B25: GĐ3: Frontend React | C25: Giao diện chung (Layout/Theme) | D25: Học React: component, props, state, hooks; khởi tạo project Vite | E25: Nhật | F25: Học tập | G25: High | H25: 10 | I25: 11 | J25: =IF(OR(H25="",I25=""),"",(I25-H25+1)*5) -> 10 | K25: To Do | L25: 0 | M25: Project client/ chạy được | N25: react.dev Learn | O25: =IF(H25="","",CFG_Start+(H25-1)*7) -> 46370 | P25: =IF(I25="","",CFG_Start+I25*7-1) -> 46383 | Q25: =IF(D25="","",IF(K25="Done","✔ Xong",IF(K25="Blocked","⛔ Blocked",IF(P25<TODAY(),"⚠ Trễ hạn",IF(O25<=TODAY(),"▶ Trong kỳ","Chưa tới"))))) -> Chưa tới | R25: =IF(J25="",0,J25*IF(K25="Done",1,IF(L25="",0,L25))) -> 0
A26: 3.2 | B26: GĐ3: Frontend React | C26: Giao diện chung (Layout/Theme) | D26: Cài Tailwind + React Router; layout chung Sidebar + Outlet + PlayerBar | E26: Nhật | F26: FE | G26: High | H26: 11 | I26: 11 | J26: =IF(OR(H26="",I26=""),"",(I26-H26+1)*5) -> 5 | K26: To Do | L26: 0 | M26: App shell | N26: Player nằm ngoài <Outlet> để không bị reset | O26: =IF(H26="","",CFG_Start+(H26-1)*7) -> 46377 | P26: =IF(I26="","",CFG_Start+I26*7-1) -> 46383 | Q26: =IF(D26="","",IF(K26="Done","✔ Xong",IF(K26="Blocked","⛔ Blocked",IF(P26<TODAY(),"⚠ Trễ hạn",IF(O26<=TODAY(),"▶ Trong kỳ","Chưa tới"))))) -> Chưa tới | R26: =IF(J26="",0,J26*IF(K26="Done",1,IF(L26="",0,L26))) -> 0
A27: 3.3 | B27: GĐ3: Frontend React | C27: Phát nhạc & Player | D27: Chuyển player sang React: store Zustand (bài hiện tại, queue, trạng thái), hook usePlayer | E27: Nhật | F27: FE | G27: High | H27: 11 | I27: 12 | J27: =IF(OR(H27="",I27=""),"",(I27-H27+1)*5) -> 10 | K27: To Do | L27: 0 | M27: usePlayer + playerStore | O27: =IF(H27="","",CFG_Start+(H27-1)*7) -> 46377 | P27: =IF(I27="","",CFG_Start+I27*7-1) -> 46390 | Q27: =IF(D27="","",IF(K27="Done","✔ Xong",IF(K27="Blocked","⛔ Blocked",IF(P27<TODAY(),"⚠ Trễ hạn",IF(O27<=TODAY(),"▶ Trong kỳ","Chưa tới"))))) -> Chưa tới | R27: =IF(J27="",0,J27*IF(K27="Done",1,IF(L27="",0,L27))) -> 0
A28: 3.4 | B28: GĐ3: Frontend React | C28: Tìm kiếm & Khám phá | D28: Trang Home, Album, Nghệ sĩ, Thể loại với dữ liệu mock | E28: Nhật | F28: FE | G28: High | H28: 12 | I28: 13 | J28: =IF(OR(H28="",I28=""),"",(I28-H28+1)*5) -> 10 | K28: To Do | L28: 0 | M28: 4 trang chính | O28: =IF(H28="","",CFG_Start+(H28-1)*7) -> 46384 | P28: =IF(I28="","",CFG_Start+I28*7-1) -> 46397 | Q28: =IF(D28="","",IF(K28="Done","✔ Xong",IF(K28="Blocked","⛔ Blocked",IF(P28<TODAY(),"⚠ Trễ hạn",IF(O28<=TODAY(),"▶ Trong kỳ","Chưa tới"))))) -> Chưa tới | R28: =IF(J28="",0,J28*IF(K28="Done",1,IF(L28="",0,L28))) -> 0
A29: 3.5 | B29: GĐ3: Frontend React | C29: Tìm kiếm & Khám phá | D29: Trang Tìm kiếm: lọc theo tên bài/nghệ sĩ phía frontend | E29: Nhật | F29: FE | G29: Medium | H29: 13 | I29: 13 | J29: =IF(OR(H29="",I29=""),"",(I29-H29+1)*5) -> 5 | K29: To Do | L29: 0 | M29: Search page | O29: =IF(H29="","",CFG_Start+(H29-1)*7) -> 46391 | P29: =IF(I29="","",CFG_Start+I29*7-1) -> 46397 | Q29: =IF(D29="","",IF(K29="Done","✔ Xong",IF(K29="Blocked","⛔ Blocked",IF(P29<TODAY(),"⚠ Trễ hạn",IF(O29<=TODAY(),"▶ Trong kỳ","Chưa tới"))))) -> Chưa tới | R29: =IF(J29="",0,J29*IF(K29="Done",1,IF(L29="",0,L29))) -> 0
A30: 3.6 | B30: GĐ3: Frontend React | C30: Phát nhạc & Player | D30: Media Session API: điều khiển từ màn hình khóa / tai nghe | E30: Nhật | F30: FE | G30: Low | H30: 13 | I30: 13 | J30: =IF(OR(H30="",I30=""),"",(I30-H30+1)*5) -> 5 | K30: To Do | L30: 0 | M30: Media controls | O30: =IF(H30="","",CFG_Start+(H30-1)*7) -> 46391 | P30: =IF(I30="","",CFG_Start+I30*7-1) -> 46397 | Q30: =IF(D30="","",IF(K30="Done","✔ Xong",IF(K30="Blocked","⛔ Blocked",IF(P30<TODAY(),"⚠ Trễ hạn",IF(O30<=TODAY(),"▶ Trong kỳ","Chưa tới"))))) -> Chưa tới | R30: =IF(J30="",0,J30*IF(K30="Done",1,IF(L30="",0,L30))) -> 0
A31: 3.7 | B31: GĐ3: Frontend React | C31: Giao diện chung (Layout/Theme) | D31: Kiểm thử: nhạc phát liên tục khi chuyển trang | E31: Nhật | F31: Testing | G31: High | H31: 13 | I31: 13 | J31: =IF(OR(H31="",I31=""),"",(I31-H31+1)*5) -> 5 | K31: To Do | L31: 0 | M31: Test case pass | O31: =IF(H31="","",CFG_Start+(H31-1)*7) -> 46391 | P31: =IF(I31="","",CFG_Start+I31*7-1) -> 46397 | Q31: =IF(D31="","",IF(K31="Done","✔ Xong",IF(K31="Blocked","⛔ Blocked",IF(P31<TODAY(),"⚠ Trễ hạn",IF(O31<=TODAY(),"▶ Trong kỳ","Chưa tới"))))) -> Chưa tới | R31: =IF(J31="",0,J31*IF(K31="Done",1,IF(L31="",0,L31))) -> 0
A32: 4.1 | B32: GĐ4: Backend & Streaming API | C32: Nền tảng & Hạ tầng | D32: Học Node.js, Express, REST API, middleware | E32: Nhật | F32: Học tập | G32: High | H32: 14 | I32: 14 | J32: =IF(OR(H32="",I32=""),"",(I32-H32+1)*5) -> 5 | K32: To Do | L32: 0 | M32: Ghi chú + demo | N32: Express Guide | O32: =IF(H32="","",CFG_Start+(H32-1)*7) -> 46398 | P32: =IF(I32="","",CFG_Start+I32*7-1) -> 46404 | Q32: =IF(D32="","",IF(K32="Done","✔ Xong",IF(K32="Blocked","⛔ Blocked",IF(P32<TODAY(),"⚠ Trễ hạn",IF(O32<=TODAY(),"▶ Trong kỳ","Chưa tới"))))) -> Chưa tới | R32: =IF(J32="",0,J32*IF(K32="Done",1,IF(L32="",0,L32))) -> 0
A33: 4.2 | B33: GĐ4: Backend & Streaming API | C33: Nền tảng & Hạ tầng | D33: Khởi tạo server/: routes-controllers-services, .env, CORS, xử lý lỗi tập trung | E33: Nhật | F33: BE | G33: High | H33: 14 | I33: 15 | J33: =IF(OR(H33="",I33=""),"",(I33-H33+1)*5) -> 10 | K33: To Do | L33: 0 | M33: Server skeleton | O33: =IF(H33="","",CFG_Start+(H33-1)*7) -> 46398 | P33: =IF(I33="","",CFG_Start+I33*7-1) -> 46411 | Q33: =IF(D33="","",IF(K33="Done","✔ Xong",IF(K33="Blocked","⛔ Blocked",IF(P33<TODAY(),"⚠ Trễ hạn",IF(O33<=TODAY(),"▶ Trong kỳ","Chưa tới"))))) -> Chưa tới | R33: =IF(J33="",0,J33*IF(K33="Done",1,IF(L33="",0,L33))) -> 0
A34: 4.3 | B34: GĐ4: Backend & Streaming API | C34: Tìm kiếm & Khám phá | D34: API catalog: GET /songs, /songs/:id, /albums, /artists (dữ liệu tạm trong code) | E34: Nhật | F34: API | G34: High | H34: 15 | I34: 15 | J34: =IF(OR(H34="",I34=""),"",(I34-H34+1)*5) -> 5 | K34: To Do | L34: 0 | M34: Catalog API v0 | O34: =IF(H34="","",CFG_Start+(H34-1)*7) -> 46405 | P34: =IF(I34="","",CFG_Start+I34*7-1) -> 46411 | Q34: =IF(D34="","",IF(K34="Done","✔ Xong",IF(K34="Blocked","⛔ Blocked",IF(P34<TODAY(),"⚠ Trễ hạn",IF(O34<=TODAY(),"▶ Trong kỳ","Chưa tới"))))) -> Chưa tới | R34: =IF(J34="",0,J34*IF(K34="Done",1,IF(L34="",0,L34))) -> 0
A35: 4.4 | B35: GĐ4: Backend & Streaming API | C35: Streaming & Lưu trữ | D35: API stream mp3 hỗ trợ HTTP Range (206 Partial Content) | E35: Nhật | F35: API | G35: High | H35: 15 | I35: 16 | J35: =IF(OR(H35="",I35=""),"",(I35-H35+1)*5) -> 10 | K35: To Do | L35: 0 | M35: GET /api/stream/:id | N35: Tự viết xử lý Range, không chỉ res.sendFile | O35: =IF(H35="","",CFG_Start+(H35-1)*7) -> 46405 | P35: =IF(I35="","",CFG_Start+I35*7-1) -> 46418 | Q35: =IF(D35="","",IF(K35="Done","✔ Xong",IF(K35="Blocked","⛔ Blocked",IF(P35<TODAY(),"⚠ Trễ hạn",IF(O35<=TODAY(),"▶ Trong kỳ","Chưa tới"))))) -> Chưa tới | R35: =IF(J35="",0,J35*IF(K35="Done",1,IF(L35="",0,L35))) -> 0
A36: 4.5 | B36: GĐ4: Backend & Streaming API | C36: Phát nhạc & Player | D36: Frontend gọi API thật bằng TanStack Query thay cho mock | E36: Nhật | F36: FE | G36: High | H36: 16 | I36: 16 | J36: =IF(OR(H36="",I36=""),"",(I36-H36+1)*5) -> 5 | K36: To Do | L36: 0 | M36: FE nối BE | O36: =IF(H36="","",CFG_Start+(H36-1)*7) -> 46412 | P36: =IF(I36="","",CFG_Start+I36*7-1) -> 46418 | Q36: =IF(D36="","",IF(K36="Done","✔ Xong",IF(K36="Blocked","⛔ Blocked",IF(P36<TODAY(),"⚠ Trễ hạn",IF(O36<=TODAY(),"▶ Trong kỳ","Chưa tới"))))) -> Chưa tới | R36: =IF(J36="",0,J36*IF(K36="Done",1,IF(L36="",0,L36))) -> 0
A37: 4.6 | B37: GĐ4: Backend & Streaming API | C37: Nền tảng & Hạ tầng | D37: Chuẩn hóa API contract: {data, message, pagination}, mã lỗi, tài liệu endpoint | E37: Nhật | F37: Docs | G37: Medium | H37: 16 | I37: 17 | J37: =IF(OR(H37="",I37=""),"",(I37-H37+1)*5) -> 10 | K37: To Do | L37: 0 | M37: API contract | N37: Cập nhật sheet 03 | O37: =IF(H37="","",CFG_Start+(H37-1)*7) -> 46412 | P37: =IF(I37="","",CFG_Start+I37*7-1) -> 46425 | Q37: =IF(D37="","",IF(K37="Done","✔ Xong",IF(K37="Blocked","⛔ Blocked",IF(P37<TODAY(),"⚠ Trễ hạn",IF(O37<=TODAY(),"▶ Trong kỳ","Chưa tới"))))) -> Chưa tới | R37: =IF(J37="",0,J37*IF(K37="Done",1,IF(L37="",0,L37))) -> 0
A38: 4.7 | B38: GĐ4: Backend & Streaming API | C38: Streaming & Lưu trữ | D38: Kiểm thử API bằng Postman; tua giữa bài trả 206 | E38: Nhật | F38: Testing | G38: High | H38: 17 | I38: 17 | J38: =IF(OR(H38="",I38=""),"",(I38-H38+1)*5) -> 5 | K38: To Do | L38: 0 | M38: Postman collection | O38: =IF(H38="","",CFG_Start+(H38-1)*7) -> 46419 | P38: =IF(I38="","",CFG_Start+I38*7-1) -> 46425 | Q38: =IF(D38="","",IF(K38="Done","✔ Xong",IF(K38="Blocked","⛔ Blocked",IF(P38<TODAY(),"⚠ Trễ hạn",IF(O38<=TODAY(),"▶ Trong kỳ","Chưa tới"))))) -> Chưa tới | R38: =IF(J38="",0,J38*IF(K38="Done",1,IF(L38="",0,L38))) -> 0
A39: 5.1 | B39: GĐ5: Database & dữ liệu nhạc | C39: Nền tảng & Hạ tầng | D39: Học SQL: SELECT, JOIN, GROUP BY, khóa chính/ngoại, index | E39: Nhật | F39: Học tập | G39: High | H39: 18 | I39: 18 | J39: =IF(OR(H39="",I39=""),"",(I39-H39+1)*5) -> 5 | K39: To Do | L39: 0 | M39: Bài tập SQLBolt | O39: =IF(H39="","",CFG_Start+(H39-1)*7) -> 46426 | P39: =IF(I39="","",CFG_Start+I39*7-1) -> 46432 | Q39: =IF(D39="","",IF(K39="Done","✔ Xong",IF(K39="Blocked","⛔ Blocked",IF(P39<TODAY(),"⚠ Trễ hạn",IF(O39<=TODAY(),"▶ Trong kỳ","Chưa tới"))))) -> Chưa tới | R39: =IF(J39="",0,J39*IF(K39="Done",1,IF(L39="",0,L39))) -> 0
A40: 5.2 | B40: GĐ5: Database & dữ liệu nhạc | C40: Nền tảng & Hạ tầng | D40: Thiết kế ERD: users, artists, albums, songs, song_artists, genres, playlists, playlist_songs, likes, follows, listen_history, downloads, lyrics | E40: Nhật | F40: Database | G40: High | H40: 18 | I40: 19 | J40: =IF(OR(H40="",I40=""),"",(I40-H40+1)*5) -> 10 | K40: To Do | L40: 0 | M40: ERD draw.io + SQL | O40: =IF(H40="","",CFG_Start+(H40-1)*7) -> 46426 | P40: =IF(I40="","",CFG_Start+I40*7-1) -> 46439 | Q40: =IF(D40="","",IF(K40="Done","✔ Xong",IF(K40="Blocked","⛔ Blocked",IF(P40<TODAY(),"⚠ Trễ hạn",IF(O40<=TODAY(),"▶ Trong kỳ","Chưa tới"))))) -> Chưa tới | R40: =IF(J40="",0,J40*IF(K40="Done",1,IF(L40="",0,L40))) -> 0
A41: 5.3 | B41: GĐ5: Database & dữ liệu nhạc | C41: Nền tảng & Hạ tầng | D41: Cài Prisma: schema, migration MySQL | E41: Nhật | F41: Database | G41: High | H41: 19 | I41: 19 | J41: =IF(OR(H41="",I41=""),"",(I41-H41+1)*5) -> 5 | K41: To Do | L41: 0 | M41: schema.prisma | O41: =IF(H41="","",CFG_Start+(H41-1)*7) -> 46433 | P41: =IF(I41="","",CFG_Start+I41*7-1) -> 46439 | Q41: =IF(D41="","",IF(K41="Done","✔ Xong",IF(K41="Blocked","⛔ Blocked",IF(P41<TODAY(),"⚠ Trễ hạn",IF(O41<=TODAY(),"▶ Trong kỳ","Chưa tới"))))) -> Chưa tới | R41: =IF(J41="",0,J41*IF(K41="Done",1,IF(L41="",0,L41))) -> 0
...

Sheet 02_Gantt Chart Tự Động
A1: 02 — GANTT CHART TỰ ĐỘNG · 4TMUSIC
A2: Tự lấy dữ liệu từ sheet 01 (không nhập tay ở đây). Thanh màu tự cập nhật theo Tuần BĐ/KT, % hoàn thành và ngày hôm nay.
A3: Tuần hiện tại: | C3: =CFG_CurWeek -> 1 | F3: Kế hoạch | J3: Đã hoàn thành | N3: Trễ hạn | R3: Tuần hiện tại | V3: ◆ Milestone
A5: Mã WBS | B5: Công việc | C5: Phụ trách | D5: Tuần BĐ | E5: Tuần KT | F5: % HT | G5: Trạng thái | H5: 1 | I5: 2 | J5: 3 | K5: 4 | L5: 5 | M5: 6 | N5: 7 | O5: 8 | P5: 9 | Q5: 10 | R5: 11 | S5: 12 | T5: 13 | U5: 14 | V5: 15 | W5: 16 | X5: 17 | Y5: 18 | Z5: 19 | AA5: 20 | AB5: 21 | AC5: 22 | AD5: 23 | AE5: 24 | AF5: 25 | AG5: 26 | AH5: 27 | AI5: 28 | AJ5: 29 | AK5: 30 | AL5: 31 | AM5: 32 | AN5: 33 | AO5: 34
B6: Ngày bắt đầu tuần → | H6: =CFG_Start+(H$5-1)*7 -> 46307 | I6: =CFG_Start+(I$5-1)*7 -> 46314 | J6: =CFG_Start+(J$5-1)*7 -> 46321 | K6: =CFG_Start+(K$5-1)*7 -> 46328 | L6: =CFG_Start+(L$5-1)*7 -> 46335 | M6: =CFG_Start+(M$5-1)*7 -> 46342 | N6: =CFG_Start+(N$5-1)*7 -> 46349 | O6: =CFG_Start+(O$5-1)*7 -> 46356 | ... AO6: =CFG_Start+(AO$5-1)*7 -> 46538
B7: Milestone → | H7: =IFERROR("◆ "&INDEX(MS_Names,MATCH(H$5,MS_Weeks,0)),"") | I7: =IFERROR("◆ "&INDEX(MS_Names,MATCH(I$5,MS_Weeks,0)),"") | J7: =IFERROR("◆ "&INDEX(MS_Names,MATCH(J$5,MS_Weeks,0)),"") | K7: =IFERROR("◆ "&INDEX(MS_Names,MATCH(K$5,MS_Weeks,0)),"") | L7: =IFERROR("◆ "&INDEX(MS_Names,MATCH(L$5,MS_Weeks,0)),"") | M7: =IFERROR("◆ "&INDEX(MS_Names,MATCH(M$5,MS_Weeks,0)),"") | N7: =IFERROR("◆ "&INDEX(MS_Names,MATCH(N$5,MS_Weeks,0)),"") | O7: =IFERROR("◆ "&INDEX(MS_Names,MATCH(O$5,MS_Weeks,0)),"") | ... AO7: =IFERROR("◆ "&INDEX(MS_Names,MATCH(AO$5,MS_Weeks,0)),"") -> ◆ Release Production
A8: =IF('01_WBS & Master Plan'!A5="","",'01_WBS & Master Plan'!A5) -> 0.1 | B8: =IF('01_WBS & Master Plan'!D5="","",'01_WBS & Master Plan'!D5) -> Học: web hoạt động thế nào — client/server, DNS, HTTP request/response, status code | C8: =IF('01_WBS & Master Plan'!E5="","",'01_WBS & Master Plan'!E5) -> Nhật | D8: =IF('01_WBS & Master Plan'!H5="","",'01_WBS & Master Plan'!H5) -> 1 | E8: =IF('01_WBS & Master Plan'!I5="","",'01_WBS & Master Plan'!I5) -> 1 | F8: =IF(B8="","",IF('01_WBS & Master Plan'!K5="Done",1,IF('01_WBS & Master Plan'!L5="",0,'01_WBS & Master Plan'!L5))) -> 0.3 | G8: =IF('01_WBS & Master Plan'!K5="","",'01_WBS & Master Plan'!K5) -> In Progress | H8: =IF(OR($D8="",$E8=""),"",IF(AND(H$5>=$D8,H$5<=$E8),IF(H$5-$D8+1<=ROUND(($E8-$D8+1)*$F8,0),2,IF(H$5<CFG_CurWeek,3,1)),"")) -> 1 | I8: =IF(OR($D8="",$E8=""),"",IF(AND(I$5>=$D8,I$5<=$E8),IF(I$5-$D8+1<=ROUND(($E8-$D8+1)*$F8,0),2,IF(I$5<CFG_CurWeek,3,1)),"")) | J8: =IF(OR($D8="",$E8=""),"",IF(AND(J$5>=$D8,J$5<=$E8),IF(J$5-$D8+1<=ROUND(($E8-$D8+1)*$F8,0),2,IF(J$5<CFG_CurWeek,3,1)),"")) | K8: =IF(OR($D8="",$E8=""),"",IF(AND(K$5>=$D8,K$5<=$E8),IF(K$5-$D8+1<=ROUND(($E8-$D8+1)*$F8,0),2,IF(K$5<CFG_CurWeek,3,1)),"")) | L8: =IF(OR($D8="",$E8=""),"",IF(AND(L$5>=$D8,L$5<=$E8),IF(L$5-$D8+1<=ROUND(($E8-$D8+1)*$F8,0),2,IF(L$5<CFG_CurWeek,3,1)),"")) | M8: =IF(OR($D8="",$E8=""),"",IF(AND(M$5>=$D8,M$5<=$E8),IF(M$5-$D8+1<=ROUND(($E8-$D8+1)*$F8,0),2,IF(M$5<CFG_CurWeek,3,1)),"")) | N8: =IF(OR($D8="",$E8=""),"",IF(AND(N$5>=$D8,N$5<=$E8),IF(N$5-$D8+1<=ROUND(($E8-$D8+1)*$F8,0),2,IF(N$5<CFG_CurWeek,3,1)),"")) | O8: =IF(OR($D8="",$E8=""),"",IF(AND(O$5>=$D8,O$5<=$E8),IF(O$5-$D8+1<=ROUND(($E8-$D8+1)*$F8,0),2,IF(O$5<CFG_CurWeek,3,1)),"")) | ... AO8: =IF(OR($D8="",$E8=""),"",IF(AND(AO$5>=$D8,AO$5<=$E8),IF(AO$5-$D8+1<=ROUND(($E8-$D8+1)*$F8,0),2,IF(AO$5<CFG_CurWeek,3,1)),""))
A9: =IF('01_WBS & Master Plan'!A6="","",'01_WBS & Master Plan'!A6) -> 0.2 | B9: =IF('01_WBS & Master Plan'!D6="","",'01_WBS & Master Plan'!D6) -> Cài môi trường: VS Code (Prettier, ESLint), Node.js LTS, Git, Postman, Chrome DevTools | C9: =IF('01_WBS & Master Plan'!E6="","",'01_WBS & Master Plan'!E6) -> Nhật | D9: =IF('01_WBS & Master Plan'!H6="","",'01_WBS & Master Plan'!H6) -> 1 | E9: =IF('01_WBS & Master Plan'!I6="","",'01_WBS & Master Plan'!I6) -> 1 | F9: =IF(B9="","",IF('01_WBS & Master Plan'!K6="Done",1,IF('01_WBS & Master Plan'!L6="",0,'01_WBS & Master Plan'!L6))) -> 0 | G9: =IF('01_WBS & Master Plan'!K6="","",'01_WBS & Master Plan'!K6) -> To Do | H9: =IF(OR($D9="",$E9=""),"",IF(AND(H$5>=$D9,H$5<=$E9),IF(H$5-$D9+1<=ROUND(($E9-$D9+1)*$F9,0),2,IF(H$5<CFG_CurWeek,3,1)),"")) -> 1 | I9: =IF(OR($D9="",$E9=""),"",IF(AND(I$5>=$D9,I$5<=$E9),IF(I$5-$D9+1<=ROUND(($E9-$D9+1)*$F9,0),2,IF(I$5<CFG_CurWeek,3,1)),"")) | J9: =IF(OR($D9="",$E9=""),"",IF(AND(J$5>=$D9,J$5<=$E9),IF(J$5-$D9+1<=ROUND(($E9-$D9+1)*$F9,0),2,IF(J$5<CFG_CurWeek,3,1)),"")) | K9: =IF(OR($D9="",$E9=""),"",IF(AND(K$5>=$D9,K$5<=$E9),IF(K$5-$D9+1<=ROUND(($E9-$D9+1)*$F9,0),2,IF(K$5<CFG_CurWeek,3,1)),"")) | L9: =IF(OR($D9="",$E9=""),"",IF(AND(L$5>=$D9,L$5<=$E9),IF(L$5-$D9+1<=ROUND(($E9-$D9+1)*$F9,0),2,IF(L$5<CFG_CurWeek,3,1)),"")) | M9: =IF(OR($D9="",$E9=""),"",IF(AND(M$5>=$D9,M$5<=$E9),IF(M$5-$D9+1<=ROUND(($E9-$D9+1)*$F9,0),2,IF(M$5<CFG_CurWeek,3,1)),"")) | N9: =IF(OR($D9="",$E9=""),"",IF(AND(N$5>=$D9,N$5<=$E9),IF(N$5-$D9+1<=ROUND(($E9-$D9+1)*$F9,0),2,IF(N$5<CFG_CurWeek,3,1)),"")) | O9: =IF(OR($D9="",$E9=""),"",IF(AND(O$5>=$D9,O$5<=$E9),IF(O$5-$D9+1<=ROUND(($E9-$D9+1)*$F9,0),2,IF(O$5<CFG_CurWeek,3,1)),"")) | ... AO9: =IF(OR($D9="",$E9=""),"",IF(AND(AO$5>=$D9,AO$5<=$E9),IF(AO$5-$D9+1<=ROUND(($E9-$D9+1)*$F9,0),2,IF(AO$5<CFG_CurWeek,3,1)),""))
A10: =IF('01_WBS & Master Plan'!A7="","",'01_WBS & Master Plan'!A7) -> 0.3 | B10: =IF('01_WBS & Master Plan'!D7="","",'01_WBS & Master Plan'!D7) -> Học Git cơ bản; tạo repo GitHub 4TMusic (client/ + server/), README, .gitignore | C10: =IF('01_WBS & Master Plan'!E7="","",'01_WBS & Master Plan'!E7) -> Nhật | D10: =IF('01_WBS & Master Plan'!H7="","",'01_WBS & Master Plan'!H7) -> 1 | E10: =IF('01_WBS & Master Plan'!I7="","",'01_WBS & Master Plan'!I7) -> 2 | F10: =IF(B10="","",IF('01_WBS & Master Plan'!K7="Done",1,IF('01_WBS & Master Plan'!L7="",0,'01_WBS & Master Plan'!L7))) -> 0 | G10: =IF('01_WBS & Master Plan'!K7="","",'01_WBS & Master Plan'!K7) -> To Do | H10: =IF(OR($D10="",$E10=""),"",IF(AND(H$5>=$D10,H$5<=$E10),IF(H$5-$D10+1<=ROUND(($E10-$D10+1)*$F10,0),2,IF(H$5<CFG_CurWeek,3,1)),"")) -> 1 | I10: =IF(OR($D10="",$E10=""),"",IF(AND(I$5>=$D10,I$5<=$E10),IF(I$5-$D10+1<=ROUND(($E10-$D10+1)*$F10,0),2,IF(I$5<CFG_CurWeek,3,1)),"")) -> 1 | J10: =IF(OR($D10="",$E10=""),"",IF(AND(J$5>=$D10,J$5<=$E10),IF(J$5-$D10+1<=ROUND(($E10-$D10+1)*$F10,0),2,IF(J$5<CFG_CurWeek,3,1)),"")) | K10: =IF(OR($D10="",$E10=""),"",IF(AND(K$5>=$D10,K$5<=$E10),IF(K$5-$D10+1<=ROUND(($E10-$D10+1)*$F10,0),2,IF(K$5<CFG_CurWeek,3,1)),"")) | L10: =IF(OR($D10="",$E10=""),"",IF(AND(L$5>=$D10,L$5<=$E10),IF(L$5-$D10+1<=ROUND(($E10-$D10+1)*$F10,0),2,IF(L$5<CFG_CurWeek,3,1)),"")) | M10: =IF(OR($D10="",$E10=""),"",IF(AND(M$5>=$D10,M$5<=$E10),IF(M$5-$D10+1<=ROUND(($E10-$D10+1)*$F10,0),2,IF(M$5<CFG_CurWeek,3,1)),"")) | N10: =IF(OR($D10="",$E10=""),"",IF(AND(N$5>=$D10,N$5<=$E10),IF(N$5-$D10+1<=ROUND(($E10-$D10+1)*$F10,0),2,IF(N$5<CFG_CurWeek,3,1)),"")) | O10: =IF(OR($D10="",$E10=""),"",IF(AND(O$5>=$D10,O$5<=$E10),IF(O$5-$D10+1<=ROUND(($E10-$D10+1)*$F10,0),2,IF(O$5<CFG_CurWeek,3,1)),"")) | ... AO10: =IF(OR($D10="",$E10=""),"",IF(AND(AO$5>=$D10,AO$5<=$E10),IF(AO$5-$D10+1<=ROUND(($E10-$D10+1)*$F10,0),2,IF(AO$5<CFG_CurWeek,3,1)),""))
A11: =IF('01_WBS & Master Plan'!A8="","",'01_WBS & Master Plan'!A8) -> 0.4 | B11: =IF('01_WBS & Master Plan'!D8="","",'01_WBS & Master Plan'!D8) -> Viết tài liệu yêu cầu rút gọn: tính năng, vai trò (Khách, User, Artist, Admin), phạm vi P1/P2 | C11: =IF('01_WBS & Master Plan'!E8="","",'01_WBS & Master Plan'!E8) -> Nhật | D11: =IF('01_WBS & Master Plan'!H8="","",'01_WBS & Master Plan'!H8) -> 2 | E11: =IF('01_WBS & Master Plan'!I8="","",'01_WBS & Master Plan'!I8) -> 2 | F11: =IF(B11="","",IF('01_WBS & Master Plan'!K8="Done",1,IF('01_WBS & Master Plan'!L8="",0,'01_WBS & Master Plan'!L8))) -> 0 | G11: =IF('01_WBS & Master Plan'!K8="","",'01_WBS & Master Plan'!K8) -> To Do | H11: =IF(OR($D11="",$E11=""),"",IF(AND(H$5>=$D11,H$5<=$E11),IF(H$5-$D11+1<=ROUND(($E11-$D11+1)*$F11,0),2,IF(H$5<CFG_CurWeek,3,1)),"")) | I11: =IF(OR($D11="",$E11=""),"",IF(AND(I$5>=$D11,I$5<=$E11),IF(I$5-$D11+1<=ROUND(($E11-$D11+1)*$F11,0),2,IF(I$5<CFG_CurWeek,3,1)),"")) -> 1 | J11: =IF(OR($D11="",$E11=""),"",IF(AND(J$5>=$D11,J$5<=$E11),IF(J$5-$D11+1<=ROUND(($E11-$D11+1)*$F11,0),2,IF(J$5<CFG_CurWeek,3,1)),"")) | K11: =IF(OR($D11="",$E11=""),"",IF(AND(K$5>=$D11,K$5<=$E11),IF(K$5-$D11+1<=ROUND(($E11-$D11+1)*$F11,0),2,IF(K$5<CFG_CurWeek,3,1)),"")) | L11: =IF(OR($D11="",$E11=""),"",IF(AND(L$5>=$D11,L$5<=$E11),IF(L$5-$D11+1<=ROUND(($E11-$D11+1)*$F11,0),2,IF(L$5<CFG_CurWeek,3,1)),"")) | M11: =IF(OR($D11="",$E11=""),"",IF(AND(M$5>=$D11,M$5<=$E11),IF(M$5-$D11+1<=ROUND(($E11-$D11+1)*$F11,0),2,IF(M$5<CFG_CurWeek,3,1)),"")) | N11: =IF(OR($D11="",$E11=""),"",IF(AND(N$5>=$D11,N$5<=$E11),IF(N$5-$D11+1<=ROUND(($E11-$D11+1)*$F11,0),2,IF(N$5<CFG_CurWeek,3,1)),"")) | O11: =IF(OR($D11="",$E11=""),"",IF(AND(O$5>=$D11,O$5<=$E11),IF(O$5-$D11+1<=ROUND(($E11-$D11+1)*$F11,0),2,IF(O$5<CFG_CurWeek,3,1)),"")) | ... AO11: =IF(OR($D11="",$E11=""),"",IF(AND(AO$5>=$D11,AO$5<=$E11),IF(AO$5-$D11+1<=ROUND(($E11-$D11+1)*$F11,0),2,IF(AO$5<CFG_CurWeek,3,1)),""))
A12: =IF('01_WBS & Master Plan'!A9="","",'01_WBS & Master Plan'!A9) -> 0.5 | B12: =IF('01_WBS & Master Plan'!D9="","",'01_WBS & Master Plan'!D9) -> Phác wireframe: Trang chủ, Tìm kiếm, Album, Nghệ sĩ, Playlist, Thư viện, Player bar, Now Playing | C12: =IF('01_WBS & Master Plan'!E9="","",'01_WBS & Master Plan'!E9) -> Nhật | D12: =IF('01_WBS & Master Plan'!H9="","",'01_WBS & Master Plan'!H9) -> 2 | E12: =IF('01_WBS & Master Plan'!I9="","",'01_WBS & Master Plan'!I9) -> 2 | F12: =IF(B12="","",IF('01_WBS & Master Plan'!K9="Done",1,IF('01_WBS & Master Plan'!L9="",0,'01_WBS & Master Plan'!L9))) -> 0 | G12: =IF('01_WBS & Master Plan'!K9="","",'01_WBS & Master Plan'!K9) -> To Do | H12: =IF(OR($D12="",$E12=""),"",IF(AND(H$5>=$D12,H$5<=$E12),IF(H$5-$D12+1<=ROUND(($E12-$D12+1)*$F12,0),2,IF(H$5<CFG_CurWeek,3,1)),"")) | I12: =IF(OR($D12="",$E12=""),"",IF(AND(I$5>=$D12,I$5<=$E12),IF(I$5-$D12+1<=ROUND(($E12-$D12+1)*$F12,0),2,IF(I$5<CFG_CurWeek,3,1)),"")) -> 1 | J12: =IF(OR($D12="",$E12=""),"",IF(AND(J$5>=$D12,J$5<=$E12),IF(J$5-$D12+1<=ROUND(($E12-$D12+1)*$F12,0),2,IF(J$5<CFG_CurWeek,3,1)),"")) | K12: =IF(OR($D12="",$E12=""),"",IF(AND(K$5>=$D12,K$5<=$E12),IF(K$5-$D12+1<=ROUND(($E12-$D12+1)*$F12,0),2,IF(K$5<CFG_CurWeek,3,1)),"")) | L12: =IF(OR($D12="",$E12=""),"",IF(AND(L$5>=$D12,L$5<=$E12),IF(L$5-$D12+1<=ROUND(($E12-$D12+1)*$F12,0),2,IF(L$5<CFG_CurWeek,3,1)),"")) | M12: =IF(OR($D12="",$E12=""),"",IF(AND(M$5>=$D12,M$5<=$E12),IF(M$5-$D12+1<=ROUND(($E12-$D12+1)*$F12,0),2,IF(M$5<CFG_CurWeek,3,1)),"")) | N12: =IF(OR($D12="",$E12=""),"",IF(AND(N$5>=$D12,N$5<=$E12),IF(N$5-$D12+1<=ROUND(($E12-$D12+1)*$F12,0),2,IF(N$5<CFG_CurWeek,3,1)),"")) | O12: =IF(OR($D12="",$E12=""),"",IF(AND(O$5>=$D12,O$5<=$E12),IF(O$5-$D12+1<=ROUND(($E12-$D12+1)*$F12,0),2,IF(O$5<CFG_CurWeek,3,1)),"")) | ... AO12: =IF(OR($D12="",$E12=""),"",IF(AND(AO$5>=$D12,AO$5<=$E12),IF(AO$5-$D12+1<=ROUND(($E12-$D12+1)*$F12,0),2,IF(AO$5<CFG_CurWeek,3,1)),""))
A13: =IF('01_WBS & Master Plan'!A10="","",'01_WBS & Master Plan'!A10) -> 0.6 | B13: =IF('01_WBS & Master Plan'!D10="","",'01_WBS & Master Plan'!D10) -> Chốt nguồn nhạc hợp pháp: đăng ký Jamendo API, tải 20–30 bài Creative Commons, lập bảng giấy phép | C13: =IF('01_WBS & Master Plan'!E10="","",'01_WBS & Master Plan'!E10) -> Nhật | D13: =IF('01_WBS & Master Plan'!H10="","",'01_WBS & Master Plan'!H10) -> 2 | E13: =IF('01_WBS & Master Plan'!I10="","",'01_WBS & Master Plan'!I10) -> 2 | F13: =IF(B13="","",IF('01_WBS & Master Plan'!K10="Done",1,IF('01_WBS & Master Plan'!L10="",0,'01_WBS & Master Plan'!L10))) -> 0 | G13: =IF('01_WBS & Master Plan'!K10="","",'01_WBS & Master Plan'!K10) -> To Do | H13: =IF(OR($D13="",$E13=""),"",IF(AND(H$5>=$D13,H$5<=$E13),IF(H$5-$D13+1<=ROUND(($E13-$D13+1)*$F13,0),2,IF(H$5<CFG_CurWeek,3,1)),"")) | I13: =IF(OR($D13="",$E13=""),"",IF(AND(I$5>=$D13,I$5<=$E13),IF(I$5-$D13+1<=ROUND(($E13-$D13+1)*$F13,0),2,IF(I$5<CFG_CurWeek,3,1)),"")) -> 1 | J13: =IF(OR($D13="",$E13=""),"",IF(AND(J$5>=$D13,J$5<=$E13),IF(J$5-$D13+1<=ROUND(($E13-$D13+1)*$F13,0),2,IF(J$5<CFG_CurWeek,3,1)),"")) | K13: =IF(OR($D13="",$E13=""),"",IF(AND(K$5>=$D13,K$5<=$E13),IF(K$5-$D13+1<=ROUND(($E13-$D13+1)*$F13,0),2,IF(K$5<CFG_CurWeek,3,1)),"")) | L13: =IF(OR($D13="",$E13=""),"",IF(AND(L$5>=$D13,L$5<=$E13),IF(L$5-$D13+1<=ROUND(($E13-$D13+1)*$F13,0),2,IF(L$5<CFG_CurWeek,3,1)),"")) | M13: =IF(OR($D13="",$E13=""),"",IF(AND(M$5>=$D13,M$5<=$E13),IF(M$5-$D13+1<=ROUND(($E13-$D13+1)*$F13,0),2,IF(M$5<CFG_CurWeek,3,1)),"")) | N13: =IF(OR($D13="",$E13=""),"",IF(AND(N$5>=$D13,N$5<=$E13),IF(N$5-$D13+1<=ROUND(($E13-$D13+1)*$F13,0),2,IF(N$5<CFG_CurWeek,3,1)),"")) | O13: =IF(OR($D13="",$E13=""),"",IF(AND(O$5>=$D13,O$5<=$E13),IF(O$5-$D13+1<=ROUND(($E13-$D13+1)*$F13,0),2,IF(O$5<CFG_CurWeek,3,1)),"")) | ... AO13: =IF(OR($D13="",$E13=""),"",IF(AND(AO$5>=$D13,AO$5<=$E13),IF(AO$5-$D13+1<=ROUND(($E13-$D13+1)*$F13,0),2,IF(AO$5<CFG_CurWeek,3,1)),""))
A14: =IF('01_WBS & Master Plan'!A11="","",'01_WBS & Master Plan'!A11) -> 1.1 | B14: =IF('01_WBS & Master Plan'!D11="","",'01_WBS & Master Plan'!D11) -> Học HTML ngữ nghĩa & CSS cơ bản (selector, box model, đơn vị) | C14: =IF('01_WBS & Master Plan'!E11="","",'01_WBS & Master Plan'!E11) -> Nhật | D14: =IF('01_WBS & Master Plan'!H11="","",'01_WBS & Master Plan'!H11) -> 3 | E14: =IF('01_WBS & Master Plan'!I11="","",'01_WBS & Master Plan'!I11) -> 3 | F14: =IF(B14="","",IF('01_WBS & Master Plan'!K11="Done",1,IF('01_WBS & Master Plan'!L11="",0,'01_WBS & Master Plan'!L11))) -> 0 | G14: =IF('01_WBS & Master Plan'!K11="","",'01_WBS & Master Plan'!K11) -> To Do | H14: =IF(OR($D14="",$E14=""),"",IF(AND(H$5>=$D14,H$5<=$E14),IF(H$5-$D14+1<=ROUND(($E14-$D14+1)*$F14,0),2,IF(H$5<CFG_CurWeek,3,1)),"")) | I14: =IF(OR($D14="",$E14=""),"",IF(AND(I$5>=$D14,I$5<=$E14),IF(I$5-$D14+1<=ROUND(($E14-$D14+1)*$F14,0),2,IF(I$5<CFG_CurWeek,3,1)),"")) | J14: =IF(OR($D14="",$E14=""),"",IF(AND(J$5>=$D14,J$5<=$E14),IF(J$5-$D14+1<=ROUND(($E14-$D14+1)*$F14,0),2,IF(J$5<CFG_CurWeek,3,1)),"")) -> 1 | K14: =IF(OR($D14="",$E14=""),"",IF(AND(K$5>=$D14,K$5<=$E14),IF(K$5-$D14+1<=ROUND(($E14-$D14+1)*$F14,0),2,IF(K$5<CFG_CurWeek,3,1)),"")) | L14: =IF(OR($D14="",$E14=""),"",IF(AND(L$5>=$D14,L$5<=$E14),IF(L$5-$D14+1<=ROUND(($E14-$D14+1)*$F14,0),2,IF(L$5<CFG_CurWeek,3,1)),"")) | M14: =IF(OR($D14="",$E14=""),"",IF(AND(M$5>=$D14,M$5<=$E14),IF(M$5-$D14+1<=ROUND(($E14-$D14+1)*$F14,0),2,IF(M$5<CFG_CurWeek,3,1)),"")) | N14: =IF(OR($D14="",$E14=""),"",IF(AND(N$5>=$D14,N$5<=$E14),IF(N$5-$D14+1<=ROUND(($E14-$D14+1)*$F14,0),2,IF(N$5<CFG_CurWeek,3,1)),"")) | O14: =IF(OR($D14="",$E14=""),"",IF(AND(O$5>=$D14,O$5<=$E14),IF(O$5-$D14+1<=ROUND(($E14-$D14+1)*$F14,0),2,IF(O$5<CFG_CurWeek,3,1)),"")) | ... AO14: =IF(OR($D14="",$E14=""),"",IF(AND(AO$5>=$D14,AO$5<=$E14),IF(AO$5-$D14+1<=ROUND(($E14-$D14+1)*$F14,0),2,IF(AO$5<CFG_CurWeek,3,1)),""))
A15: =IF('01_WBS & Master Plan'!A12="","",'01_WBS & Master Plan'!A12) -> 1.2 | B15: =IF('01_WBS & Master Plan'!D12="","",'01_WBS & Master Plan'!D12) -> Học Flexbox, Grid, responsive (media query, mobile-first) | C15: =IF('01_WBS & Master Plan'!E12="","",'01_WBS & Master Plan'!E12) -> Nhật | D15: =IF('01_WBS & Master Plan'!H12="","",'01_WBS & Master Plan'!H12) -> 3 | E15: =IF('01_WBS & Master Plan'!I12="","",'01_WBS & Master Plan'!I12) -> 4 | F15: =IF(B15="","",IF('01_WBS & Master Plan'!K12="Done",1,IF('01_WBS & Master Plan'!L12="",0,'01_WBS & Master Plan'!L12))) -> 0 | G15: =IF('01_WBS & Master Plan'!K12="","",'01_WBS & Master Plan'!K12) -> To Do | H15: =IF(OR($D15="",$E15=""),"",IF(AND(H$5>=$D15,H$5<=$E15),IF(H$5-$D15+1<=ROUND(($E15-$D15+1)*$F15,0),2,IF(H$5<CFG_CurWeek,3,1)),"")) | I15: =IF(OR($D15="",$E15=""),"",IF(AND(I$5>=$D15,I$5<=$E15),IF(I$5-$D15+1<=ROUND(($E15-$D15+1)*$F15,0),2,IF(I$5<CFG_CurWeek,3,1)),"")) | J15: =IF(OR($D15="",$E15=""),"",IF(AND(J$5>=$D15,J$5<=$E15),IF(J$5-$D15+1<=ROUND(($E15-$D15+1)*$F15,0),2,IF(J$5<CFG_CurWeek,3,1)),"")) -> 1 | K15: =IF(OR($D15="",$E15=""),"",IF(AND(K$5>=$D15,K$5<=$E15),IF(K$5-$D15+1<=ROUND(($E15-$D15+1)*$F15,0),2,IF(K$5<CFG_CurWeek,3,1)),"")) -> 1 | L15: =IF(OR($D15="",$E15=""),"",IF(AND(L$5>=$D15,L$5<=$E15),IF(L$5-$D15+1<=ROUND(($E15-$D15+1)*$F15,0),2,IF(L$5<CFG_CurWeek,3,1)),"")) | M15: =IF(OR($D15="",$E15=""),"",IF(AND(M$5>=$D15,M$5<=$E15),IF(M$5-$D15+1<=ROUND(($E15-$D15+1)*$F15,0),2,IF(M$5<CFG_CurWeek,3,1)),"")) | N15: =IF(OR($D15="",$E15=""),"",IF(AND(N$5>=$D15,N$5<=$E15),IF(N$5-$D15+1<=ROUND(($E15-$D15+1)*$F15,0),2,IF(N$5<CFG_CurWeek,3,1)),"")) | O15: =IF(OR($D15="",$E15=""),"",IF(AND(O$5>=$D15,O$5<=$E15),IF(O$5-$D15+1<=ROUND(($E15-$D15+1)*$F15,0),2,IF(O$5<CFG_CurWeek,3,1)),"")) | ... AO15: =IF(OR($D15="",$E15=""),"",IF(AND(AO$5>=$D15,AO$5<=$E15),IF(AO$5-$D15+1<=ROUND(($E15-$D15+1)*$F15,0),2,IF(AO$5<CFG_CurWeek,3,1)),""))
A16: =IF('01_WBS & Master Plan'!A13="","",'01_WBS & Master Plan'!A13) -> 1.3 | B16: =IF('01_WBS & Master Plan'!D13="","",'01_WBS & Master Plan'!D13) -> Dựng layout tĩnh: sidebar menu, header + ô tìm kiếm, vùng nội dung | C16: =IF('01_WBS & Master Plan'!E13="","",'01_WBS & Master Plan'!E13) -> Nhật | D16: =IF('01_WBS & Master Plan'!H13="","",'01_WBS & Master Plan'!H13) -> 4 | E16: =IF('01_WBS & Master Plan'!I13="","",'01_WBS & Master Plan'!I13) -> 4 | F16: =IF(B16="","",IF('01_WBS & Master Plan'!K13="Done",1,IF('01_WBS & Master Plan'!L13="",0,'01_WBS & Master Plan'!L13))) -> 0 | G16: =IF('01_WBS & Master Plan'!K13="","",'01_WBS & Master Plan'!K13) -> To Do | H16: =IF(OR($D16="",$E16=""),"",IF(AND(H$5>=$D16,H$5<=$E16),IF(H$5-$D16+1<=ROUND(($E16-$D16+1)*$F16,0),2,IF(H$5<CFG_CurWeek,3,1)),"")) | I16: =IF(OR($D16="",$E16=""),"",IF(AND(I$5>=$D16,I$5<=$E16),IF(I$5-$D16+1<=ROUND(($E16-$D16+1)*$F16,0),2,IF(I$5<CFG_CurWeek,3,1)),"")) | J16: =IF(OR($D16="",$E16=""),"",IF(AND(J$5>=$D16,J$5<=$E16),IF(J$5-$D16+1<=ROUND(($E16-$D16+1)*$F16,0),2,IF(J$5<CFG_CurWeek,3,1)),"")) | K16: =IF(OR($D16="",$E16=""),"",IF(AND(K$5>=$D16,K$5<=$E16),IF(K$5-$D16+1<=ROUND(($E16-$D16+1)*$F16,0),2,IF(K$5<CFG_CurWeek,3,1)),"")) -> 1 | L16: =IF(OR($D16="",$E16=""),"",IF(AND(L$5>=$D16,L$5<=$E16),IF(L$5-$D16+1<=ROUND(($E16-$D16+1)*$F16,0),2,IF(L$5<CFG_CurWeek,3,1)),"")) | M16: =IF(OR($D16="",$E16=""),"",IF(AND(M$5>=$D16,M$5<=$E16),IF(M$5-$D16+1<=ROUND(($E16-$D16+1)*$F16,0),2,IF(M$5<CFG_CurWeek,3,1)),"")) | N16: =IF(OR($D16="",$E16=""),"",IF(AND(N$5>=$D16,N$5<=$E16),IF(N$5-$D16+1<=ROUND(($E16-$D16+1)*$F16,0),2,IF(N$5<CFG_CurWeek,3,1)),"")) | O16: =IF(OR($D16="",$E16=""),"",IF(AND(O$5>=$D16,O$5<=$E16),IF(O$5-$D16+1<=ROUND(($E16-$D16+1)*$F16,0),2,IF(O$5<CFG_CurWeek,3,1)),"")) | ... AO16: =IF(OR($D16="",$E16=""),"",IF(AND(AO$5>=$D16,AO$5<=$E16),IF(AO$5-$D16+1<=ROUND(($E16-$D16+1)*$F16,0),2,IF(AO$5<CFG_CurWeek,3,1)),""))
A17: =IF('01_WBS & Master Plan'!A14="","",'01_WBS & Master Plan'!A14) -> 1.4 | B17: =IF('01_WBS & Master Plan'!D14="","",'01_WBS & Master Plan'!D14) -> Dựng trang chủ tĩnh: lưới album, danh sách bài nổi bật, thể loại | C17: =IF('01_WBS & Master Plan'!E14="","",'01_WBS & Master Plan'!E14) -> Nhật | D17: =IF('01_WBS & Master Plan'!H14="","",'01_WBS & Master Plan'!H14) -> 4 | E17: =IF('01_WBS & Master Plan'!I14="","",'01_WBS & Master Plan'!I14) -> 5 | F17: =IF(B17="","",IF('01_WBS & Master Plan'!K14="Done",1,IF('01_WBS & Master Plan'!L14="",0,'01_WBS & Master Plan'!L14))) -> 0 | G17: =IF('01_WBS & Master Plan'!K14="","",'01_WBS & Master Plan'!K14) -> To Do | H17: =IF(OR($D17="",$E17=""),"",IF(AND(H$5>=$D17,H$5<=$E17),IF(H$5-$D17+1<=ROUND(($E17-$D17+1)*$F17,0),2,IF(H$5<CFG_CurWeek,3,1)),"")) | I17: =IF(OR($D17="",$E17=""),"",IF(AND(I$5>=$D17,I$5<=$E17),IF(I$5-$D17+1<=ROUND(($E17-$D17+1)*$F17,0),2,IF(I$5<CFG_CurWeek,3,1)),"")) | J17: =IF(OR($D17="",$E17=""),"",IF(AND(J$5>=$D17,J$5<=$E17),IF(J$5-$D17+1<=ROUND(($E17-$D17+1)*$F17,0),2,IF(J$5<CFG_CurWeek,3,1)),"")) | K17: =IF(OR($D17="",$E17=""),"",IF(AND(K$5>=$D17,K$5<=$E17),IF(K$5-$D17+1<=ROUND(($E17-$D17+1)*$F17,0),2,IF(K$5<CFG_CurWeek,3,1)),"")) -> 1 | L17: =IF(OR($D17="",$E17=""),"",IF(AND(L$5>=$D17,L$5<=$E17),IF(L$5-$D17+1<=ROUND(($E17-$D17+1)*$F17,0),2,IF(L$5<CFG_CurWeek,3,1)),"")) -> 1 | M17: =IF(OR($D17="",$E17=""),"",IF(AND(M$5>=$D17,M$5<=$E17),IF(M$5-$D17+1<=ROUND(($E17-$D17+1)*$F17,0),2,IF(M$5<CFG_CurWeek,3,1)),"")) | N17: =IF(OR($D17="",$E17=""),"",IF(AND(N$5>=$D17,N$5<=$E17),IF(N$5-$D17+1<=ROUND(($E17-$D17+1)*$F17,0),2,IF(N$5<CFG_CurWeek,3,1)),"")) | O17: =IF(OR($D17="",$E17=""),"",IF(AND(O$5>=$D17,O$5<=$E17),IF(O$5-$D17+1<=ROUND(($E17-$D17+1)*$F17,0),2,IF(O$5<CFG_CurWeek,3,1)),"")) | ... AO17: =IF(OR($D17="",$E17=""),"",IF(AND(AO$5>=$D17,AO$5<=$E17),IF(AO$5-$D17+1<=ROUND(($E17-$D17+1)*$F17,0),2,IF(AO$5<CFG_CurWeek,3,1)),""))
A18: =IF('01_WBS & Master Plan'!A15="","",'01_WBS & Master Plan'!A15) -> 1.5 | B18: =IF('01_WBS & Master Plan'!D15="","",'01_WBS & Master Plan'!D15) -> Dựng thanh Player cố định dưới màn hình (ảnh bìa, tên bài, nút, thanh tiến trình) | C18: =IF('01_WBS & Master Plan'!E15="","",'01_WBS & Master Plan'!E15) -> Nhật | D18: =IF('01_WBS & Master Plan'!H15="","",'01_WBS & Master Plan'!H15) -> 5 | E18: =IF('01_WBS & Master Plan'!I15="","",'01_WBS & Master Plan'!I15) -> 5 | F18: =IF(B18="","",IF('01_WBS & Master Plan'!K15="Done",1,IF('01_WBS & Master Plan'!L15="",0,'01_WBS & Master Plan'!L15))) -> 0 | G18: =IF('01_WBS & Master Plan'!K15="","",'01_WBS & Master Plan'!K15) -> To Do | H18: =IF(OR($D18="",$E18=""),"",IF(AND(H$5>=$D18,H$5<=$E18),IF(H$5-$D18+1<=ROUND(($E18-$D18+1)*$F18,0),2,IF(H$5<CFG_CurWeek,3,1)),"")) | I18: =IF(OR($D18="",$E18=""),"",IF(AND(I$5>=$D18,I$5<=$E18),IF(I$5-$D18+1<=ROUND(($E18-$D18+1)*$F18,0),2,IF(I$5<CFG_CurWeek,3,1)),"")) | J18: =IF(OR($D18="",$E18=""),"",IF(AND(J$5>=$D18,J$5<=$E18),IF(J$5-$D18+1<=ROUND(($E18-$D18+1)*$F18,0),2,IF(J$5<CFG_CurWeek,3,1)),"")) | K18: =IF(OR($D18="",$E18=""),"",IF(AND(K$5>=$D18,K$5<=$E18),IF(K$5-$D18+1<=ROUND(($E18-$D18+1)*$F18,0),2,IF(K$5<CFG_CurWeek,3,1)),"")) | L18: =IF(OR($D18="",$E18=""),"",IF(AND(L$5>=$D18,L$5<=$E18),IF(L$5-$D18+1<=ROUND(($E18-$D18+1)*$F18,0),2,IF(L$5<CFG_CurWeek,3,1)),"")) -> 1 | M18: =IF(OR($D18="",$E18=""),"",IF(AND(M$5>=$D18,M$5<=$E18),IF(M$5-$D18+1<=ROUND(($E18-$D18+1)*$F18,0),2,IF(M$5<CFG_CurWeek,3,1)),"")) | N18: =IF(OR($D18="",$E18=""),"",IF(AND(N$5>=$D18,N$5<=$E18),IF(N$5-$D18+1<=ROUND(($E18-$D18+1)*$F18,0),2,IF(N$5<CFG_CurWeek,3,1)),"")) | O18: =IF(OR($D18="",$E18=""),"",IF(AND(O$5>=$D18,O$5<=$E18),IF(O$5-$D18+1<=ROUND(($E18-$D18+1)*$F18,0),2,IF(O$5<CFG_CurWeek,3,1)),"")) | ... AO18: =IF(OR($D18="",$E18=""),"",IF(AND(AO$5>=$D18,AO$5<=$E18),IF(AO$5-$D18+1<=ROUND(($E18-$D18+1)*$F18,0),2,IF(AO$5<CFG_CurWeek,3,1)),""))
